[2024-12-05 03:22:39,222] {taskinstance.py:1159} INFO - Dependencies all met for <TaskInstance: crypto_data_pipeline.save_to_postgres scheduled__2024-12-05T02:00:00+00:00 [queued]>
[2024-12-05 03:22:39,228] {taskinstance.py:1159} INFO - Dependencies all met for <TaskInstance: crypto_data_pipeline.save_to_postgres scheduled__2024-12-05T02:00:00+00:00 [queued]>
[2024-12-05 03:22:39,228] {taskinstance.py:1356} INFO - 
--------------------------------------------------------------------------------
[2024-12-05 03:22:39,228] {taskinstance.py:1357} INFO - Starting attempt 2 of 4
[2024-12-05 03:22:39,228] {taskinstance.py:1358} INFO - 
--------------------------------------------------------------------------------
[2024-12-05 03:22:39,237] {taskinstance.py:1377} INFO - Executing <Task(PythonOperator): save_to_postgres> on 2024-12-05 02:00:00+00:00
[2024-12-05 03:22:39,239] {standard_task_runner.py:52} INFO - Started process 72 to run task
[2024-12-05 03:22:39,242] {standard_task_runner.py:79} INFO - Running: ['airflow', 'tasks', 'run', 'crypto_data_pipeline', 'save_to_***', 'scheduled__2024-12-05T02:00:00+00:00', '--job-id', '22', '--raw', '--subdir', 'DAGS_FOLDER/crypto_data_pipeline.py', '--cfg-path', '/tmp/tmpebsh46rd', '--error-file', '/tmp/tmp1ck2kcks']
[2024-12-05 03:22:39,242] {standard_task_runner.py:80} INFO - Job 22: Subtask save_to_***
[2024-12-05 03:22:39,255] {logging_mixin.py:115} WARNING - /home/airflow/.local/lib/python3.7/site-packages/airflow/configuration.py:470 DeprecationWarning: The sql_alchemy_conn option in [core] has been moved to the sql_alchemy_conn option in [database] - the old setting has been used, but please update your config.
[2024-12-05 03:22:39,284] {task_command.py:369} INFO - Running <TaskInstance: crypto_data_pipeline.save_to_postgres scheduled__2024-12-05T02:00:00+00:00 [running]> on host 85834e6b4d18
[2024-12-05 03:22:39,339] {taskinstance.py:1571} INFO - Exporting the following env vars:
AIRFLOW_CTX_DAG_OWNER=airflow
AIRFLOW_CTX_DAG_ID=crypto_data_pipeline
AIRFLOW_CTX_TASK_ID=save_to_***
AIRFLOW_CTX_EXECUTION_DATE=2024-12-05T02:00:00+00:00
AIRFLOW_CTX_TRY_NUMBER=2
AIRFLOW_CTX_DAG_RUN_ID=scheduled__2024-12-05T02:00:00+00:00
[2024-12-05 03:22:39,340] {taskinstance.py:1889} ERROR - Task failed with exception
Traceback (most recent call last):
  File "/home/airflow/.local/lib/python3.7/site-packages/airflow/operators/python.py", line 171, in execute
    return_value = self.execute_callable()
  File "/home/airflow/.local/lib/python3.7/site-packages/airflow/operators/python.py", line 189, in execute_callable
    return self.python_callable(*self.op_args, **self.op_kwargs)
  File "/opt/airflow/dags/crypto_data_pipeline.py", line 50, in save_to_postgres
    with open(TEMP_FILE_PATH, 'r') as f:
FileNotFoundError: [Errno 2] No such file or directory: '/tmp/crypto_data.json'
[2024-12-05 03:22:39,349] {taskinstance.py:1400} INFO - Marking task as UP_FOR_RETRY. dag_id=crypto_data_pipeline, task_id=save_to_***, execution_date=20241205T020000, start_date=20241205T032239, end_date=20241205T032239
[2024-12-05 03:22:39,355] {standard_task_runner.py:97} ERROR - Failed to execute job 22 for task save_to_*** ([Errno 2] No such file or directory: '/tmp/crypto_data.json'; 72)
[2024-12-05 03:22:39,373] {local_task_job.py:156} INFO - Task exited with return code 1
[2024-12-05 03:22:39,403] {local_task_job.py:273} INFO - 0 downstream tasks scheduled from follow-on schedule check
