[2024-12-05 03:14:44,120] {taskinstance.py:1159} INFO - Dependencies all met for <TaskInstance: crypto_data_pipeline.save_to_postgres manual__2024-12-05T03:14:38.592343+00:00 [queued]>
[2024-12-05 03:14:44,126] {taskinstance.py:1159} INFO - Dependencies all met for <TaskInstance: crypto_data_pipeline.save_to_postgres manual__2024-12-05T03:14:38.592343+00:00 [queued]>
[2024-12-05 03:14:44,126] {taskinstance.py:1356} INFO - 
--------------------------------------------------------------------------------
[2024-12-05 03:14:44,126] {taskinstance.py:1357} INFO - Starting attempt 1 of 4
[2024-12-05 03:14:44,126] {taskinstance.py:1358} INFO - 
--------------------------------------------------------------------------------
[2024-12-05 03:14:44,134] {taskinstance.py:1377} INFO - Executing <Task(PythonOperator): save_to_postgres> on 2024-12-05 03:14:38.592343+00:00
[2024-12-05 03:14:44,136] {standard_task_runner.py:52} INFO - Started process 73 to run task
[2024-12-05 03:14:44,138] {standard_task_runner.py:79} INFO - Running: ['airflow', 'tasks', 'run', 'crypto_data_pipeline', 'save_to_***', 'manual__2024-12-05T03:14:38.592343+00:00', '--job-id', '6', '--raw', '--subdir', 'DAGS_FOLDER/crypto_data_pipeline.py', '--cfg-path', '/tmp/tmp_93273no', '--error-file', '/tmp/tmpbot2_okl']
[2024-12-05 03:14:44,138] {standard_task_runner.py:80} INFO - Job 6: Subtask save_to_***
[2024-12-05 03:14:44,177] {task_command.py:369} INFO - Running <TaskInstance: crypto_data_pipeline.save_to_postgres manual__2024-12-05T03:14:38.592343+00:00 [running]> on host 85834e6b4d18
[2024-12-05 03:14:44,230] {taskinstance.py:1571} INFO - Exporting the following env vars:
AIRFLOW_CTX_DAG_OWNER=airflow
AIRFLOW_CTX_DAG_ID=crypto_data_pipeline
AIRFLOW_CTX_TASK_ID=save_to_***
AIRFLOW_CTX_EXECUTION_DATE=2024-12-05T03:14:38.592343+00:00
AIRFLOW_CTX_TRY_NUMBER=1
AIRFLOW_CTX_DAG_RUN_ID=manual__2024-12-05T03:14:38.592343+00:00
[2024-12-05 03:14:44,231] {taskinstance.py:1889} ERROR - Task failed with exception
Traceback (most recent call last):
  File "/home/airflow/.local/lib/python3.7/site-packages/airflow/operators/python.py", line 171, in execute
    return_value = self.execute_callable()
  File "/home/airflow/.local/lib/python3.7/site-packages/airflow/operators/python.py", line 189, in execute_callable
    return self.python_callable(*self.op_args, **self.op_kwargs)
  File "/opt/airflow/dags/crypto_data_pipeline.py", line 55, in save_to_postgres
    dbname="crypto_db", user="postgres", password="postgres", host="localhost"
  File "/home/airflow/.local/lib/python3.7/site-packages/psycopg2/__init__.py", line 122, in connect
    conn = _connect(dsn, connection_factory=connection_factory, **kwasync)
psycopg2.OperationalError: connection to server at "localhost" (::1), port 5432 failed: Connection refused
	Is the server running on that host and accepting TCP/IP connections?
connection to server at "localhost" (127.0.0.1), port 5432 failed: Connection refused
	Is the server running on that host and accepting TCP/IP connections?

[2024-12-05 03:14:44,238] {taskinstance.py:1400} INFO - Marking task as UP_FOR_RETRY. dag_id=crypto_data_pipeline, task_id=save_to_***, execution_date=20241205T031438, start_date=20241205T031444, end_date=20241205T031444
[2024-12-05 03:14:44,245] {standard_task_runner.py:97} ERROR - Failed to execute job 6 for task save_to_*** (connection to server at "localhost" (::1), port 5432 failed: Connection refused
	Is the server running on that host and accepting TCP/IP connections?
connection to server at "localhost" (127.0.0.1), port 5432 failed: Connection refused
	Is the server running on that host and accepting TCP/IP connections?
; 73)
[2024-12-05 03:14:44,270] {local_task_job.py:156} INFO - Task exited with return code 1
[2024-12-05 03:14:44,295] {local_task_job.py:273} INFO - 0 downstream tasks scheduled from follow-on schedule check
